Workbook

Sheet Balance Sheet
A1: Walmart Inc. (WMT) — Balance Sheet
A2: Fiscal Year Ended January 31 | Amounts in $Millions | Source: WMT FY2025 10-K (SEC EDGAR)
A3: Line Item | B3: FY2025 (Jan 31, 2025) | C3: FY2024 (Jan 31, 2024) | D3: Notes / Source
A4: ASSETS
A5: Current Assets
A6: Cash and cash equivalents | B6: 9300 | C6: 8625 | D6: 10-K Balance Sheet
A7: Receivables, net | B7: 8796 | C7: 7933 | D7: 10-K Balance Sheet
A8: Inventories | B8: 56435 | C8: 56576 | D8: 10-K Balance Sheet
A9: Prepaid expenses and other | B9: 2927 | C9: 2521 | D9: 10-K Balance Sheet
A10: Total Current Assets | B10: =SUM(B6:B9) -> 77458 | C10: =SUM(C6:C9) -> 75655
A11: Non-Current Assets
A12: Property and equipment, net | B12: 110810 | C12: 100760 | D12: 10-K Balance Sheet
A13: Operating lease right-of-use assets | B13: 13673 | C13: 13555 | D13: 10-K Balance Sheet
A14: Finance lease right-of-use assets, net | B14: 5855 | C14: 4919 | D14: 10-K Balance Sheet
A15: Goodwill | B15: 28113 | C15: 28174 | D15: 10-K Balance Sheet
A16: Other long-term assets | B16: 17071 | C16: 20134 | D16: 10-K Balance Sheet
A17: Total Non-Current Assets | B17: =SUM(B12:B16) -> 175522 | C17: =SUM(C12:C16) -> 167542
A18: TOTAL ASSETS | B18: =B10+B17 -> 252980 | C18: =C10+C17 -> 243197
A20: LIABILITIES & EQUITY
A21: Current Liabilities
A22: Short-term borrowings | B22: 878 | C22: 372 | D22: 10-K Balance Sheet
A23: Accounts payable | B23: 56812 | C23: 53742 | D23: 10-K Balance Sheet
A24: Accrued liabilities | B24: 28759 | C24: 31126 | D24: 10-K Balance Sheet
A25: Long-term debt due within one year | B25: 3447 | C25: 4191 | D25: 10-K Balance Sheet
A26: Operating lease obligations due within one year | B26: 1487 | C26: 1473 | D26: 10-K Balance Sheet
A27: Finance lease obligations due within one year | B27: 725 | C27: 567 | D27: 10-K Balance Sheet
A28: Accrued income taxes | B28: 307 | C28: 727 | D28: 10-K Balance Sheet
A29: Total Current Liabilities | B29: =SUM(B22:B28) -> 92415 | C29: =SUM(C22:C28) -> 92198
A30: Non-Current Liabilities
A31: Long-term debt | B31: 36132 | C31: 34649 | D31: 10-K Balance Sheet
A32: Long-term operating lease obligations | B32: 12961 | C32: 13197 | D32: 10-K Balance Sheet
A33: Long-term finance lease obligations | B33: 4838 | C33: 4001 | D33: 10-K Balance Sheet
A34: Deferred income taxes and other | B34: 14016 | C34: 13703 | D34: 10-K Balance Sheet
A35: Total Non-Current Liabilities | B35: =SUM(B31:B34) -> 67947 | C35: =SUM(C31:C34) -> 65550
A36: TOTAL LIABILITIES | B36: =B29+B35 -> 160362 | C36: =C29+C35 -> 157748
A38: SHAREHOLDERS' EQUITY
A39: Common stock | B39: 805 | C39: 808 | D39: 10-K Balance Sheet
A40: Capital in excess of par value | B40: 4544 | C40: 4430 | D40: 10-K Balance Sheet
A41: Retained earnings | B41: 89814 | C41: 83135 | D41: 10-K Balance Sheet
A42: Accumulated other comprehensive loss | B42: -11302 | C42: -11680 | D42: 10-K Balance Sheet
...

Sheet Income Statement
A1: Walmart Inc. (WMT) — Income Statement
A2: Fiscal Year Ended January 31 | Amounts in $Millions | Source: WMT FY2025 10-K (SEC EDGAR)
A3: Line Item | B3: FY2025 (Jan 31, 2025) | C3: FY2024 (Jan 31, 2024) | D3: Notes / Source
A4: REVENUE
A5: Net sales | B5: 680985 | C5: 648125 | D5: 10-K Income Statement
A6: Membership and other income | B6: 4448 | C6: 4255 | D6: 10-K Income Statement
A7: Total Revenue | B7: =B5+B6 -> 685433 | C7: =C5+C6 -> 652380
A8: COSTS & EXPENSES
A9: Cost of sales | B9: 511753 | C9: 490142 | D9: 10-K Income Statement
A10: Gross Profit | B10: =B5-B9 -> 169232 | C10: =C5-C9 -> 157983
A11: Operating, SG&A expenses | B11: 139884 | C11: 130971 | D11: 10-K Income Statement
A12: of which: Depreciation & Amortization (included in above) | B12: 12978 | C12: 11853 | D12: 10-K CF Statement
A13: Operating Income (EBIT) | B13: =B10-B11 -> 29348 | C13: =C10-C11 -> 27012
A14: Interest income | B14: 483 | C14: 546 | D14: 10-K Income Statement
A15: Interest expense (debt) | B15: -2728 | C15: -2683 | D15: 10-K Income Statement
A16: Other gains / (losses) | B16: -794 | C16: -3027 | D16: 10-K Income Statement
A17: Income Before Taxes | B17: =B13+B14+B15+B16 -> 26309 | C17: =C13+C14+C15+C16 -> 21848
A18: Provision for income taxes | B18: 6152 | C18: 5578 | D18: 10-K Income Statement
A19: Consolidated Net Income | B19: =B17-B18 -> 20157 | C19: =C17-C18 -> 16270
A20: Less: Net income attributable to noncontrolling interest | B20: 721 | C20: 759 | D20: 10-K Income Statement
A21: Net Income Attributable to Walmart | B21: =B19-B20 -> 19436 | C21: =C19-C20 -> 15511
A22: Dividends paid | B22: 6640 | C22: 6140 | D22: 10-K Cash Flow Statement

Sheet Cash Flow
A1: Walmart Inc. (WMT) — Cash Flow Statement
A2: Fiscal Year Ended January 31 | Amounts in $Millions | Source: WMT FY2025 10-K (SEC EDGAR)
A3: Line Item | B3: FY2025 | C3: FY2024 | D3: Notes
A4: OPERATING ACTIVITIES
A5: Consolidated net income | B5: 19436 | C5: 16270 | D5: 10-K CF Statement
A6: Depreciation and amortization | B6: 12978 | C6: 11853 | D6: 10-K CF Statement
A7: Net unrealized and realized (gains) losses | B7: 794 | C7: 3193 | D7: 10-K CF Statement
A8: Deferred income taxes | B8: -697 | C8: -175 | D8: 10-K CF Statement
A9: Other operating activities | B9: 1842 | C9: 2642 | D9: 10-K CF Statement
A10: Changes in working capital items | B10: 2047 | C10: 1993 | D10: 10-K CF Statement
A11: Net Cash from Operating Activities | B11: 36400 | C11: 35726 | D11: 10-K CF Statement
A12: INVESTING ACTIVITIES
A13: Payments for property and equipment (Capex) | B13: -23740 | C13: -20606 | D13: 10-K CF Statement
A14: Proceeds from disposal of property & equipment | B14: 348 | C14: 250 | D14: 10-K CF Statement
A15: Acquisitions and other investing | B15: -2109 | C15: -1066 | D15: 10-K CF Statement
A16: Net Cash from Investing Activities | B16: -25501 | C16: -21287 | D16: 10-K CF Statement
A17: FINANCING ACTIVITIES
A18: Net change in short-term borrowings | B18: 506 | C18: 512 | D18: 10-K CF Statement
A19: Proceeds from issuance of long-term debt | B19: 4977 | C19: 4967 | D19: 10-K CF Statement
A20: Repayments of long-term debt | B20: -4527 | C20: -4217 | D20: 10-K CF Statement
A21: Dividends paid | B21: -6640 | C21: -6140 | D21: 10-K CF Statement
A22: Purchase of Company stock | B22: -4488 | C22: -2779 | D22: 10-K CF Statement
A23: Other financing activities | B23: -1432 | C23: -828 | D23: 10-K CF Statement
A24: Net Cash from Financing Activities | B24: -11604 | C24: -8485 | D24: 10-K CF Statement
A26: Free Cash Flow (OCF - Capex) | B26: =B11+B13 -> 12660 | C26: =C11+C13 -> 15120

Sheet Ratios
A1: Walmart Inc. (WMT) — Financial Ratio Analysis | FY2025
A2: Color Key: Yellow = Raw Input | Blue = Analyst Assumption | Green = Cross-Sheet Formula | Gray = Computed Output
A3: Input / Ratio | B3: Named Range | C3: Value | D3: Formula (Named-Range Notation) | E3: Notes
A4: SECTION 1 — MARKET & ANALYST INPUTS
A5: Share price (Jan 31, 2025) | B5: share_price | C5: 95.28 | D5: Market close Jan 31, 2025
A6: Shares outstanding (millions, diluted) | B6: shares_outstanding | C6: 8081 | D6: FY2025 10-K, diluted shares
A7: Cost of capital (WACC) | B7: cost_capital | C7: 0.076 | D7: Estimated 7.6% WACC
A8: Tax rate (effective) | B8: tax_rate | C8: 0.2338 | D8: FY2025 effective rate from 10-K
A9: SECTION 2 — DERIVED INPUTS
A10: Market capitalization ($M) | B10: market_capitalization | C10: =C5*C6 -> 769957.68 | D10: 'share_price × shares_outstanding | E10: share_price × shares_outstanding
A11: After-tax operating income ($M) | B11: currentYear_after_tax_operating_income | C11: ='Income Statement'!B13*(1-C8) -> 22486.438 | D11: 'inc_ebit × (1 - tax_rate) | E11: EBIT × (1 - tax_rate)
A12: Daily sales average ($M) | B12: currentYear_daily_sales_average | C12: ='Income Statement'!B5/365 -> 1865.7123 | D12: 'inc_sales / 365 | E12: net_sales / 365
A13: Net working capital ($M) | B13: currentYear_working_capital_net | C13: ='Balance Sheet'!B10-'Balance Sheet'!B29 -> -14957 | D13: 'bal_assets_current_fy25 - bal_liabilities_current_fy25 | E13: current assets - current liabilities
A14: Start-of-Year Items (FY2024 Balance Sheet = Start of FY2025)
A15: Start-of-year equity ($M) | B15: startYear_equity | C15: ='Balance Sheet'!C43 -> 76693 | D15: FY2024 BS equity
A16: Start-of-year inventories ($M) | B16: startYear_inventories | C16: ='Balance Sheet'!C8 -> 56576 | D16: FY2024 BS inv
A17: Start-of-year receivables ($M) | B17: startYear_receivables | C17: ='Balance Sheet'!C7 -> 7933 | D17: FY2024 BS recv
A18: Start-of-year total assets ($M) | B18: startYear_total_assets | C18: ='Balance Sheet'!C18 -> 243197 | D18: FY2024 BS total assets
A19: Start-of-year long-term debt ($M) | B19: startYear_long_term_debt | C19: ='Balance Sheet'!C31 -> 34649 | D19: FY2024 BS LT debt
A20: Start-of-year total capitalization ($M) | B20: startYear_total_capitalization | C20: =C19+C15 -> 111342 | D20: LT debt + equity (FY2024)
A21: Current-Year Items (FY2025)
A22: Current-year equity ($M) | B22: currentYear_equity | C22: ='Balance Sheet'!B43 -> 83861
A23: Current-year total assets ($M) | B23: currentYear_total_assets | C23: ='Balance Sheet'!B18 -> 252980
A24: Current-year long-term debt ($M) | B24: currentYear_long_term_debt | C24: ='Balance Sheet'!B31 -> 36132
A25: Current-year current liabilities ($M) | B25: currentYear_liabilities_current | C25: ='Balance Sheet'!B29 -> 92415
A26: Current-year current assets ($M) | B26: currentYear_assets_current | C26: ='Balance Sheet'!B10 -> 77458
A27: Current-year cash ($M) | B27: currentYear_cash | C27: ='Balance Sheet'!B6 -> 9300
A28: Current-year total capitalization ($M) | B28: currentYear_total_capitalization | C28: =C24+C22 -> 119993
A29: Average Items
A30: Average equity ($M) | B30: avg_equity | C30: =AVERAGE(C15,C22) -> 80277
A31: Average total assets ($M) | B31: avg_total_assets | C31: =AVERAGE(C18,C23) -> 248088.5
A32: Average total capitalization ($M) | B32: avg_total_capitalization | C32: =AVERAGE(C20,C28) -> 115667.5
A34: SECTION 3 — PERFORMANCE RATIOS
A35: Market Value Added (MVA) | B35: ratio_MVA | C35: =C10-C22 -> 686096.68 | D35: 'market_capitalization - currentyear_equity | E35: Market cap minus book equity
A36: Market-to-Book Ratio | B36: ratio_market_to_book | C36: =C10/C22 -> 9.1813558 | D36: 'market_capitalization / currentyear_equity | E36: Price premium over book value
A37: Economic Value Added (EVA) | B37: ratio_EVA | C37: =C11-(C7*C20) -> 14024.446 | D37: 'currentyear_after_tax_operating_income - (cost_capital × startYear_total_capitalization)) | E37: Value created above cost of capital
A39: SECTION 4 — PROFITABILITY RATIOS (Start-of-Year Denominators)
A40: ROA (start-of-year) | B40: ratio_ROA_start | C40: =C11/C18 -> 0.092461821 | D40: 'currentyear_after_tax_operating_income / startyear_total_assets
A41: ROC (start-of-year) | B41: ratio_ROC_start | C41: =C11/C20 -> 0.20195827 | D41: 'currentyear_after_tax_operating_income / startyear_total_capitalization
A42: ROE (start-of-year) | B42: ratio_ROE_start | C42: ='Income Statement'!B21/C15 -> 0.253426 | D42: 'inc_net / startyear_equity
...

Sheet Notes
A1: Walmart Inc. (WMT) — Model Notes, Assumptions & Data Sources
A2: Company | B2: Walmart Inc. (NYSE: WMT)
A3: Fiscal Year | B3: FY2025 — fiscal year ended January 31, 2025
A4: Prior Year | B4: FY2024 — fiscal year ended January 31, 2024
A5: Currency | B5: All figures in USD millions unless otherwise noted
A6: Primary Source | B6: WMT FY2025 Form 10-K filed with SEC ~February 20, 2025
A7: CF Source | B7: WMT FY2025 Q4 Earnings Release (Form 8-K, Exhibit 99.1), February 20, 2025
A8: Share Price | B8: $95.28 — market close January 31, 2025 (fiscal year-end)
A9: Shares Outstanding | B9: 8,081 million diluted shares per FY2025 10-K
A10: WACC / Cost of Capital | B10: 7.6% — estimated WACC based on market beta, risk-free rate, and capital structure
A11: Effective Tax Rate | B11: 23.38% — FY2025 effective rate per 10-K income tax disclosure
A12: Depreciation | B12: Taken from Cash Flow Statement adjustments ($12,978M FY2025)
A13: Start-of-Year Values | B13: FY2024 ending balance sheet used as FY2025 start-of-year for ROA, ROE, ROC denominators
... A19: File Naming | B19: Follows course convention: lastname-first-stage2-model.xlsx
